<?xml version="1.0" ?>
<sdf version='1.6'>
  <model name='12DOFManipulator'>
    <link name="link1">
      <pose frame=''>0 0 0 0 0 0</pose>
      <inertial>
        <pose frame='link1'>0.5 0 0 0 0 0</pose>
        <mass>1.0</mass>
        <inertia>
          <ixx>0.005</ixx>
          <ixy>0.</ixy>
          <ixz>0.0</ixz>
          <iyy>0.006</iyy>
          <izz>0.003</izz>
        </inertia>        
      </inertial>
      <!--collision name='collision'>
        <pose frame=''>0.5 0 0 0 0 0</pose>        
        <geometry>
          <box>
            <size>1 0.15 0.15</size>
          </box>          
        </geometry>      
      </collision-->  
      <visual name='visual'>
        <pose frame=''>0.5 0 0 0 0 0</pose>      
        <geometry>
          <box>
            <size>1 0.15 0.15</size>
          </box>          
        </geometry>
        <material>          
          <ambient>1.0 0.5019607843137254902 0 1.0</ambient>
        </material>      
      </visual>
      <self_collide>0</self_collide>
    </link>
    
    <link name="link2">
      <pose frame=''>1 0 0 0 0 0</pose>
      <inertial>
        <pose frame='link2'>0.5 0 0 0 0 0</pose>
        <mass>1.0</mass>
        <inertia>
          <ixx>0.005</ixx>
          <ixy>0.</ixy>
          <ixz>0.0</ixz>
          <iyy>0.006</iyy>
          <izz>0.003</izz>
        </inertia>  
      </inertial>
      <!--collision name='collision'>
        <pose frame=''>0.5 0 0 0 0 0</pose>        
        <geometry>
          <box>
            <size>1 0.15 0.15</size>
          </box>          
        </geometry>      
      </collision-->  
      <visual name='visual'>
        <pose frame=''>0.5 0 0 0 0 0</pose>      
        <geometry>
          <box>
            <size>1 0.15 0.15</size>
          </box>          
        </geometry>
        <material>          
          <ambient>1.0 0.5019607843137254902 0 1.0</ambient>
        </material>      
      </visual>
      <self_collide>0</self_collide>  
    </link>
    
    <link name="link3">
      <pose frame=''>2 0 0 0 0 0</pose>
      <inertial>
        <pose frame='link3'>0.5 0 0 0 0 0</pose>
        <mass>1.0</mass>
        <inertia>
          <ixx>0.005</ixx>
          <ixy>0.</ixy>
          <ixz>0.0</ixz>
          <iyy>0.006</iyy>
          <izz>0.003</izz>
        </inertia>  
      </inertial>
      <!--collision name='collision'>
        <pose frame=''>0.5 0 0 0 0 0</pose>        
        <geometry>
          <box>
            <size>1 0.15 0.15</size>
          </box>          
        </geometry>      
      </collision-->  
      <visual name='visual'>
        <pose frame=''>0.5 0 0 0 0 0</pose>      
        <geometry>
          <box>
            <size>1 0.15 0.15</size>
          </box>          
        </geometry>
        <material>          
          <ambient>1.0 0.5019607843137254902 0 1.0</ambient>
        </material>      
      </visual>
      <self_collide>0</self_collide>  
    </link>
    
    <link name="link4">
      <pose frame=''>3 0 0 0 0 0</pose>
      <inertial>
        <pose frame='link4'>0.5 0 0 0 0 0</pose>
        <mass>1.0</mass>
        <inertia>
          <ixx>0.005</ixx>
          <ixy>0.</ixy>
          <ixz>0.0</ixz>
          <iyy>0.006</iyy>
          <izz>0.003</izz>
        </inertia>  
      </inertial>
      <!--collision name='collision'>
        <pose frame=''>0.5 0 0 0 0 0</pose>        
        <geometry>
          <box>
            <size>1 0.15 0.15</size>
          </box>          
        </geometry>      
      </collision-->  
      <visual name='visual'>
        <pose frame=''>0.5 0 0 0 0 0</pose>      
        <geometry>
          <box>
            <size>1 0.15 0.15</size>
          </box>          
        </geometry>
        <material>          
          <ambient>1.0 0.5019607843137254902 0 1.0</ambient>
        </material>      
      </visual>      
      <self_collide>0</self_collide>  
    </link>
    
    <link name="link5">
      <pose frame=''>4 0 0 0 0 0</pose>
      <inertial>
        <pose frame='link5'>0.5 0 0 0 0 0</pose>
        <mass>1.0</mass>
        <inertia>
          <ixx>0.005</ixx>
          <ixy>0.</ixy>
          <ixz>0.0</ixz>
          <iyy>0.006</iyy>
          <izz>0.003</izz>
        </inertia>  
      </inertial>
      <collision name='collision'>
        <pose frame=''>0.5 0 0 0 0 0</pose>        
        <geometry>
          <box>
            <size>1 0.15 0.15</size>
          </box>          
        </geometry>      
      </collision>  
      <visual name='visual'>
        <pose frame=''>0.5 0 0 0 0 0</pose>      
        <geometry>
          <box>
            <size>1 0.15 0.15</size>
          </box>          
        </geometry>
        <material>          
          <ambient>1.0 0.5019607843137254902 0 1.0</ambient>
        </material>      
      </visual>      
      <self_collide>0</self_collide>  
    </link>
    
    <link name="link6">
      <pose frame=''>5 0 0 0 0 0</pose>
      <inertial>
        <pose frame='link6'>0.5 0 0 0 0 0</pose>
        <mass>1.0</mass>
        <inertia>
          <ixx>0.005</ixx>
          <ixy>0.</ixy>
          <ixz>0.0</ixz>
          <iyy>0.006</iyy>
          <izz>0.003</izz>
        </inertia>  
      </inertial>
      <collision name='collision'>
        <pose frame=''>0.5 0 0 0 0 0</pose>        
        <geometry>
          <box>
            <size>1 0.15 0.15</size>
          </box>          
        </geometry>      
      </collision>  
      <visual name='visual'>
        <pose frame=''>0.5 0 0 0 0 0</pose>      
        <geometry>
          <box>
            <size>1 0.15 0.15</size>
          </box>          
        </geometry>
        <material>          
          <ambient>1.0 0.5019607843137254902 0 1.0</ambient>
        </material>      
      </visual>      
      <self_collide>0</self_collide>  
    </link>
    
    <link name="link7">
      <pose frame=''>6 0 0 0 0 0</pose>
      <inertial>
        <pose frame='link7'>0.5 0 0 0 0 0</pose>
        <mass>1.0</mass>
        <inertia>
          <ixx>0.005</ixx>
          <ixy>0.</ixy>
          <ixz>0.0</ixz>
          <iyy>0.006</iyy>
          <izz>0.003</izz>
        </inertia>  
      </inertial>
      <collision name='collision'>
        <pose frame=''>0.5 0 0 0 0 0</pose>        
        <geometry>
          <box>
            <size>1 0.15 0.15</size>
          </box>          
        </geometry>      
      </collision>  
      <visual name='visual'>
        <pose frame=''>0.5 0 0 0 0 0</pose>      
        <geometry>
          <box>
            <size>1 0.15 0.15</size>
          </box>          
        </geometry>
        <material>          
          <ambient>1.0 0.5019607843137254902 0 1.0</ambient>
        </material>      
      </visual>      
      <self_collide>0</self_collide>  
    </link>
    
    <link name="link8">
      <pose frame=''>7 0 0 0 0 0</pose>
      <inertial>
        <pose frame='link8'>0.5 0 0 0 0 0</pose>
        <mass>1.0</mass>
        <inertia>
          <ixx>0.005</ixx>
          <ixy>0.</ixy>
          <ixz>0.0</ixz>
          <iyy>0.006</iyy>
          <izz>0.003</izz>
        </inertia>  
      </inertial>
      <collision name='collision'>
        <pose frame=''>0.5 0 0 0 0 0</pose>        
        <geometry>
          <box>
            <size>1 0.15 0.15</size>
          </box>          
        </geometry>      
      </collision>  
      <visual name='visual'>
        <pose frame=''>0.5 0 0 0 0 0</pose>      
        <geometry>
          <box>
            <size>1 0.15 0.15</size>
          </box>          
        </geometry>
        <material>          
          <ambient>1.0 0.5019607843137254902 0 1.0</ambient>
        </material>      
      </visual>      
      <self_collide>0</self_collide>  
    </link>
    
    <link name="link9">
      <pose frame=''>8 0 0 0 0 0</pose>
      <inertial>
        <pose frame='link9'>0.5 0 0 0 0 0</pose>
        <mass>1.0</mass>
        <inertia>
          <ixx>0.005</ixx>
          <ixy>0.</ixy>
          <ixz>0.0</ixz>
          <iyy>0.006</iyy>
          <izz>0.003</izz>
        </inertia>  
      </inertial>
      <collision name='collision'>
        <pose frame=''>0.5 0 0 0 0 0</pose>        
        <geometry>
          <box>
            <size>1 0.15 0.15</size>
          </box>          
        </geometry>      
      </collision>  
      <visual name='visual'>
        <pose frame=''>0.5 0 0 0 0 0</pose>      
        <geometry>
          <box>
            <size>1 0.15 0.15</size>
          </box>          
        </geometry>
        <material>          
          <ambient>1.0 0.5019607843137254902 0 1.0</ambient>
        </material>      
      </visual>      
      <self_collide>0</self_collide>  
    </link>
    
    <link name="link10">
      <pose frame=''>9 0 0 0 0 0</pose>
      <inertial>
        <pose frame='link10'>0.5 0 0 0 0 0</pose>
        <mass>1.0</mass>
        <inertia>
          <ixx>0.005</ixx>
          <ixy>0.</ixy>
          <ixz>0.0</ixz>
          <iyy>0.006</iyy>
          <izz>0.003</izz>
        </inertia>  
      </inertial>
      <collision name='collision'>
        <pose frame=''>0.5 0 0 0 0 0</pose>        
        <geometry>
          <box>
            <size>1 0.15 0.15</size>
          </box>          
        </geometry>      
      </collision>  
      <visual name='visual'>
        <pose frame=''>0.5 0 0 0 0 0</pose>      
        <geometry>
          <box>
            <size>1 0.15 0.15</size>
          </box>          
        </geometry>
        <material>          
          <ambient>1.0 0.5019607843137254902 0 1.0</ambient>
        </material>      
      </visual>      
      <self_collide>0</self_collide>  
    </link>
    
    <link name="link11">
      <pose frame=''>10 0 0 0 0 0</pose>
      <inertial>
        <pose frame='link11'>0.5 0 0 0 0 0</pose>
        <mass>1.0</mass>
        <inertia>
          <ixx>0.005</ixx>
          <ixy>0.</ixy>
          <ixz>0.0</ixz>
          <iyy>0.006</iyy>
          <izz>0.003</izz>
        </inertia>  
      </inertial>
      <collision name='collision'>
        <pose frame=''>0.5 0 0 0 0 0</pose>        
        <geometry>
          <box>
            <size>1 0.15 0.15</size>
          </box>          
        </geometry>      
      </collision>  
      <visual name='visual'>
        <pose frame=''>0.5 0 0 0 0 0</pose>      
        <geometry>
          <box>
            <size>1 0.15 0.15</size>
          </box>          
        </geometry>
        <material>          
          <ambient>1.0 0.5019607843137254902 0 1.0</ambient>
        </material>      
      </visual>      
      <self_collide>0</self_collide>  
    </link>
    
     <link name="link12">
      <pose frame=''>11 0 0 0 0 0</pose>
      <inertial>
        <pose frame='link12'>0.5 0 0 0 0 0</pose>
        <mass>1.0</mass>
        <inertia>
          <ixx>0.005</ixx>
          <ixy>0.</ixy>
          <ixz>0.0</ixz>
          <iyy>0.006</iyy>
          <izz>0.003</izz>
        </inertia>  
      </inertial>
      <collision name='collision'>
        <pose frame=''>0.5 0 0 0 0 0</pose>        
        <geometry>
          <box>
            <size>1 0.15 0.15</size>
          </box>          
        </geometry>      
      </collision>  
      <visual name='visual'>
        <pose frame=''>0.5 0 0 0 0 0</pose>      
        <geometry>
          <box>
            <size>1 0.15 0.15</size>
          </box>          
        </geometry>
        <material>          
          <ambient>1.0 0.5019607843137254902 0 1.0</ambient>
        </material>      
      </visual>      
      <self_collide>0</self_collide>  
    </link>   
    
    <link name="endEffector">
      <pose frame=''>12.0625 0 0 0 0 0</pose>      
      <inertial>
        <pose frame='endEffector'>0 0 0 0 0 0</pose>
        <mass>1.0</mass>
        <inertia>
          <ixx>0.005</ixx>
          <ixy>0.</ixy>
          <ixz>0.0</ixz>
          <iyy>0.006</iyy>
          <izz>0.003</izz>
        </inertia>  
      </inertial>
      <collision name='endEffector_collision'>
        <pose frame=''>0 0 0 0 0 0</pose>        
        <geometry>
          <box>
            <size>0.125 0.1 0.1</size>
          </box>          
        </geometry>      
      </collision>  
      <visual name='endEffector_visual'>
        <pose frame=''>0 0 0 0 0 0</pose>      
        <geometry>
          <box>
            <size>0.125 0.1 0.1</size>
          </box>          
        </geometry>
        <material>          
          <ambient>1.0 0.5019607843137254902 0 1.0</ambient>
        </material>      
      </visual>      
      <self_collide>0</self_collide>  
    </link>
    
    <joint name="joint1" type="revolute">
      <parent>world</parent>
      <child>link1</child>
      <axis>
        <xyz>0 0 1</xyz>      
        <limit>
          <lower>-1000</lower>
          <upper>1000</upper>
          <velocity>6</velocity>
          <effort>50</effort>
        </limit>
        <dynamics>
          <damping>1.0</damping>
          <friction>0.2</friction>
        </dynamics>
        <use_parent_model_frame>1</use_parent_model_frame> 
      </axis>
      <physics>
        <ode>
          <implicit_spring_damper>1</implicit_spring_damper>
          <bounce>0</bounce>
          <limit>
            <erp>0.9</erp>
            <cfm>0</cfm>
          </limit>
        </ode>
      </physics>    
    </joint>
    
    <joint name="joint2" type="revolute">
      <parent>link1</parent>
      <child>link2</child>
      <axis>
        <xyz>0 1 0</xyz>      
        <limit>
          <lower>-1000</lower>
          <upper>1000</upper>
          <velocity>2</velocity>
          <effort>30</effort>
        </limit>
        <dynamics>
          <damping>1.0</damping>
          <friction>0.2</friction>
        </dynamics>
        <use_parent_model_frame>1</use_parent_model_frame> 
      </axis>
      <physics>
        <ode>
          <implicit_spring_damper>1</implicit_spring_damper>
          <bounce>0</bounce>
          <limit>
            <erp>0.9</erp>
            <cfm>0</cfm>
          </limit>
        </ode>
      </physics>    
    </joint>
    
    <joint name="joint3" type="revolute">
      <parent>link2</parent>
      <child>link3</child>
      <axis>
        <xyz>0 1 0</xyz>      
        <limit>
          <lower>-1000</lower>
          <upper>1000</upper>
          <velocity>2</velocity>
          <effort>40</effort>
        </limit>
        <dynamics>
          <damping>1.0</damping>
          <friction>0.2</friction>
        </dynamics>
        <use_parent_model_frame>1</use_parent_model_frame> 
      </axis>
      <physics>
        <ode>
          <implicit_spring_damper>1</implicit_spring_damper>
          <bounce>0</bounce>
          <limit>
            <erp>0.9</erp>
            <cfm>0</cfm>
          </limit>
        </ode>
      </physics>
    </joint>
    
    <joint name="joint4" type="revolute">
      <parent>link3</parent>
      <child>link4</child>
      <axis>
        <xyz>0 0 1</xyz>      
        <limit>
          <lower>-1000</lower>
          <upper>1000</upper>
          <velocity>2</velocity>
          <effort>5</effort>
        </limit>
        <dynamics>
          <damping>1.0</damping>
          <friction>0.2</friction>
        </dynamics>
        <use_parent_model_frame>1</use_parent_model_frame> 
      </axis>
      <physics>
        <ode>
          <implicit_spring_damper>1</implicit_spring_damper>
          <bounce>0</bounce>
          <limit>
            <erp>0.9</erp>
            <cfm>0</cfm>
          </limit>
        </ode>
      </physics>    
    </joint>
    
    <joint name="joint5" type="revolute">
      <parent>link4</parent>
      <child>link5</child>
      <axis>
        <xyz>0 0 1</xyz>      
        <limit>
          <lower>-1000</lower>
          <upper>1000</upper>
          <velocity>2</velocity>
          <effort>5</effort>
        </limit>
        <dynamics>
          <damping>1.0</damping>
          <friction>0.2</friction>
        </dynamics>
        <use_parent_model_frame>1</use_parent_model_frame> 
      </axis>
      <physics>
        <ode>
          <implicit_spring_damper>1</implicit_spring_damper>
          <bounce>0</bounce>
          <limit>
            <erp>0.9</erp>
            <cfm>0</cfm>
          </limit>
        </ode>
      </physics>    
    </joint>
    
    <joint name="joint6" type="revolute">
      <parent>link5</parent>
      <child>link6</child>
      <axis>
        <xyz>0 1 0</xyz>      
        <limit>
          <lower>-1000</lower>
          <upper>1000</upper>
          <velocity>2</velocity>
          <effort>5</effort>
        </limit>
        <dynamics>
          <damping>1.0</damping>
          <friction>0.2</friction>
        </dynamics>
        <use_parent_model_frame>1</use_parent_model_frame> 
      </axis>
      <physics>
        <ode>
          <implicit_spring_damper>1</implicit_spring_damper>
          <bounce>0</bounce>
          <limit>
            <erp>0.9</erp>
            <cfm>0</cfm>
          </limit>
        </ode>
      </physics>    
    </joint>
    
    <joint name="joint7" type="revolute">
      <parent>link6</parent>
      <child>link7</child>
      <axis>
        <xyz>0 0 1</xyz>      
        <limit>
          <lower>-1000</lower>
          <upper>1000</upper>
          <velocity>2</velocity>
          <effort>5</effort>
        </limit>
        <dynamics>
          <damping>1.0</damping>
          <friction>0.2</friction>
        </dynamics>
        <use_parent_model_frame>1</use_parent_model_frame> 
      </axis>
      <physics>
        <ode>
          <implicit_spring_damper>1</implicit_spring_damper>
          <bounce>0</bounce>
          <limit>
            <erp>0.9</erp>
            <cfm>0</cfm>
          </limit>
        </ode>
      </physics>    
    </joint>
    
    <joint name="joint8" type="revolute">
      <parent>link7</parent>
      <child>link8</child>
      <axis>
        <xyz>0 0 1</xyz>      
        <limit>
          <lower>-1000</lower>
          <upper>1000</upper>
          <velocity>2</velocity>
          <effort>5</effort>
        </limit>
        <dynamics>
          <damping>1.0</damping>
          <friction>0.2</friction>
        </dynamics>
        <use_parent_model_frame>1</use_parent_model_frame> 
      </axis>
      <physics>
        <ode>
          <implicit_spring_damper>1</implicit_spring_damper>
          <bounce>0</bounce>
          <limit>
            <erp>0.9</erp>
            <cfm>0</cfm>
          </limit>
        </ode>
      </physics>    
    </joint>
    
    <joint name="joint9" type="revolute">
      <parent>link8</parent>
      <child>link9</child>
      <axis>
        <xyz>0 0 1</xyz>      
        <limit>
          <lower>-1000</lower>
          <upper>1000</upper>
          <velocity>2</velocity>
          <effort>5</effort>
        </limit>
        <dynamics>
          <damping>1.0</damping>
          <friction>0.2</friction>
        </dynamics>
        <use_parent_model_frame>1</use_parent_model_frame> 
      </axis>
      <physics>
        <ode>
          <implicit_spring_damper>1</implicit_spring_damper>
          <bounce>0</bounce>
          <limit>
            <erp>0.9</erp>
            <cfm>0</cfm>
          </limit>
        </ode>
      </physics>    
    </joint>
    
    <joint name="joint10" type="revolute">
      <parent>link9</parent>
      <child>link10</child>
      <axis>
        <xyz>0 0 1</xyz>      
        <limit>
          <lower>-1000</lower>
          <upper>1000</upper>
          <velocity>2</velocity>
          <effort>5</effort>
        </limit>
        <dynamics>
          <damping>1.0</damping>
          <friction>0.2</friction>
        </dynamics>
        <use_parent_model_frame>1</use_parent_model_frame> 
      </axis>
      <physics>
        <ode>
          <implicit_spring_damper>1</implicit_spring_damper>
          <bounce>0</bounce>
          <limit>
            <erp>0.9</erp>
            <cfm>0</cfm>
          </limit>
        </ode>
      </physics>    
    </joint>
    
    <joint name="joint11" type="revolute">
      <parent>link10</parent>
      <child>link11</child>
      <axis>
        <xyz>0 0 1</xyz>      
        <limit>
          <lower>-1000</lower>
          <upper>1000</upper>
          <velocity>2</velocity>
          <effort>5</effort>
        </limit>
        <dynamics>
          <damping>1.0</damping>
          <friction>0.2</friction>
        </dynamics>
        <use_parent_model_frame>1</use_parent_model_frame> 
      </axis>
      <physics>
        <ode>
          <implicit_spring_damper>1</implicit_spring_damper>
          <bounce>0</bounce>
          <limit>
            <erp>0.9</erp>
            <cfm>0</cfm>
          </limit>
        </ode>
      </physics>    
    </joint>
    
    <joint name="joint12" type="revolute">
      <parent>link11</parent>
      <child>link12</child>
      <axis>
        <xyz>0 0 1</xyz>      
        <limit>
          <lower>-1000</lower>
          <upper>1000</upper>
          <velocity>2</velocity>
          <effort>5</effort>
        </limit>
        <dynamics>
          <damping>1.0</damping>
          <friction>0.2</friction>
        </dynamics>
        <use_parent_model_frame>1</use_parent_model_frame> 
      </axis>
      <physics>
        <ode>
          <implicit_spring_damper>1</implicit_spring_damper>
          <bounce>0</bounce>
          <limit>
            <erp>0.9</erp>
            <cfm>0</cfm>
          </limit>
        </ode>
      </physics>    
    </joint>
    
    <joint name="joint13" type="fixed">
      <parent>link12</parent>
      <child>endEffector</child>        
    </joint>    
  </model>

</sdf>
